<?xml version="1.0" encoding="UTF-8"?>
<robot name = "HipExo_NR">
	<link name = "ground">
		<inertial>
			<origin xyz="0 0 0" rpy="0 0 0"/>
			<mass value = "1e-06" />
			<inertia ixx="1e-06" ixy="0" ixz="0" iyy ="1e-06" iyz ="0" izz="1e-06" />
		</inertial>
	</link>
	<link name = "exo_waist">
		<inertial>
			<origin xyz="-0.070805 -0.00415 -0.0016" rpy="0 0 0"/>
			<mass value = "2.5" />
			<inertia ixx="0.0651" ixy="-0.00124" ixz="-7.9e-05" iyy ="0.06775" iyz ="-6.57e-05" izz="0.02219" />
		</inertial>
		<visual>
			<geometry>
				<mesh filename="./meshes2/exo_waist.stl"/>
			</geometry>
		</visual>
	</link>
	<link name = "exo_shaft_r">
		<inertial>
			<origin xyz="0 -0.01416 -0.00622" rpy="0 0 0"/>
			<mass value = "0.12169" />
			<inertia ixx="9.047e-05" ixy="0" ixz="0" iyy ="2.4608e-05" iyz ="7.69e-07" izz="0.000112214" />
		</inertial>
		<visual>
			<origin xyz="0.015  0.084  -0.0375" rpy = "0  -0  0"/>
			<geometry>
				<mesh filename="./meshes2/Shaft_1.stl"  scale="0.00075  0.00075  0.00075"/>
			</geometry>
			<material name="">
				<color rgba = "0.66       0.66       0.66  1"/>
			</material>
		</visual>
	</link>
	<link name = "exo_shaft_l">
		<inertial>
			<origin xyz="0 -0.01416 0.006225" rpy="0 0 0"/>
			<mass value = "0.12169" />
			<inertia ixx="9.047e-05" ixy="0" ixz="0" iyy ="2.4608e-05" iyz ="-7.69e-07" izz="0.000112214" />
		</inertial>
		<visual>
			<origin xyz="0.015  0.084  0.2575" rpy = "0  -0  0"/>
			<geometry>
				<mesh filename="./meshes2/Shaft_2.stl"  scale="0.00075  0.00075  0.00075"/>
			</geometry>
			<material name="">
				<color rgba = "0.66       0.66       0.66  1"/>
			</material>
		</visual>
	</link>
	<link name = "exo_hinge_r">
		<inertial>
			<origin xyz="0 -0.0678875 -0.005023" rpy="0 0 0"/>
			<mass value = "0.12115" />
			<inertia ixx="0.000436196" ixy="0" ixz="0" iyy ="2.44553e-05" iyz ="2.94435e-05" izz="0.000454219" />
		</inertial>
		<visual>
			<origin xyz="0.015  0.130875  -0.031875" rpy = "0  -0  0"/>
			<geometry>
				<mesh filename="./meshes2/Link_r5.stl"  scale="0.00075  0.00075  0.00075"/>
			</geometry>
			<material name="">
				<color rgba = "0.66       0.66       0.66  1"/>
			</material>
		</visual>
	</link>
	<link name = "exo_hinge_l">
		<inertial>
			<origin xyz="0 -0.0678875 0.005023" rpy="0 0 0"/>
			<mass value = "0.12115" />
			<inertia ixx="0.000436196" ixy="0" ixz="0" iyy ="2.44553e-05" iyz ="-2.94435e-05" izz="0.000454219" />
		</inertial>
		<visual>
			<origin xyz="0.015  0.130875  0.251875" rpy = "0  -0  0"/>
			<geometry>
				<mesh filename="./meshes2/Link_l5.stl"  scale="0.00075  0.00075  0.00075"/>
			</geometry>
			<material name="">
				<color rgba = "0.66       0.66       0.66  1"/>
			</material>
		</visual>
	</link>
	<link name = "strap_r">
		<inertial>
			<origin xyz="0 -0.03 -0.071175" rpy="0 0 0"/>
			<mass value = "0.15038" />
			<inertia ixx="0.000753818" ixy="0" ixz="6.6e-08" iyy ="0.00145702" iyz ="0" izz="0.000863603" />
		</inertial>
		<visual>
			<origin xyz="0  0.25  -0.02" rpy = "0  -0  0"/>
			<geometry>
				<mesh filename="./meshes2/Strap_r.stl"  scale="0.00075  0.00075  0.00075"/>
			</geometry>
			<material name="">
				<color rgba = "0.66       0.66       0.66  1"/>
			</material>
		</visual>
	</link>
	<link name = "strap_l">
		<inertial>
			<origin xyz="0 -0.03 0.071175" rpy="0 0 0"/>
			<mass value = "0.15038" />
			<inertia ixx="0.000753818" ixy="0" ixz="6.6e-08" iyy ="0.00145702" iyz ="0" izz="0.000863603" />
		</inertial>
		<visual>
			<origin xyz="0.02  0.25  0.24" rpy = "0  -0  0"/>
			<geometry>
				<mesh filename="./meshes2/Strap_l.stl"  scale="0.00075  0.00075  0.00075"/>
			</geometry>
			<material name="">
				<color rgba = "0.66       0.66       0.66  1"/>
			</material>
		</visual>
	</link>
	<joint name="ground_exo_waist" type="fixed">
		<origin xyz="0  0  0" rpy="0  -0  0"/>
		<parent link="ground"/>
		<child link="exo_waist"/>
		<axis xyz="0  1  0"/>
		<limit lower="-1" upper="2" effort="1e2" velocity="1e2"/>
	</joint>
	<joint name="exo_hip_flexion_r" type="revolute">
		<origin xyz="-0.065  -0.084  0.1575" rpy="0  -0  0"/>
		<parent link="exo_waist"/>
		<child link="exo_shaft_r"/>
		<axis xyz="0  0  1"/>
		<limit lower="-2.0944" upper="2.0944" effort="1e2" velocity="1e2"/>
	</joint>
	<joint name="exo_hip_flexion_l" type="revolute">
		<origin xyz="-0.065  -0.084  -0.1575" rpy="0  -0  0"/>
		<parent link="exo_waist"/>
		<child link="exo_shaft_l"/>
		<axis xyz="0  0  1"/>
		<limit lower="-2.0944" upper="2.0944" effort="1e2" velocity="1e2"/>
	</joint>
	<joint name="exo_hipadd_r" type="fixed">
		<origin xyz="0  -0.046875  -0.005625" rpy="0  -0  0"/>
		<parent link="exo_shaft_r"/>
		<child link="exo_hinge_r"/>
		<axis xyz="1  0  0"/>
		<limit lower="-0.349066" upper="0.349066" effort="1e2" velocity="1e2"/>
	</joint>
	<joint name="exo_hipadd_l" type="fixed">
		<origin xyz="-0  -0.046875  0.005625" rpy="0  -0  0"/>
		<parent link="exo_shaft_l"/>
		<child link="exo_hinge_l"/>
		<axis xyz="1  0  0"/>
		<limit lower="-0.349066" upper="0.349066" effort="1e2" velocity="1e2"/>
	</joint>
	<joint name="strap_r_joint" type="fixed">
		<origin xyz="0  -0.146875  -0.005625" rpy="0  -0  0"/>
		<parent link="exo_hinge_r"/>
		<child link="strap_r"/>
	</joint>
	<joint name="strap_l_joint" type="fixed">
		<origin xyz="0  -0.146875  0.005625" rpy="0  -0  0"/>
		<parent link="exo_hinge_l"/>
		<child link="strap_l"/>
	</joint>
</robot>
